Workbook

Sheet Transmittal
B2: NEW BALTIMORE 4.8 kV CONVERSION PROGRAM
B3: Overhead Material Quantities Transmittal
B5: Contract No. | C5: 4400008681
B6: From | C6: HWC Construction / CVR Engineering
B7: To | C7: DTE Electric Company — Attn: John Chang, Supply Chain
B8: Transmittal No. | C8: (enter)
B9: Transmittal Date | C9: (enter)
B10: Prepared Under Direction Of | C10: Jim Codling, SVP Engineering, CVR Engineering
B11: Yellow cells: complete before issuing.
B13: PURPOSE
B14: In response to DTE’s request for confirmed overhead material quantities, this package transmits the source-validated material quantity reconciliation for the New Baltimore overhead conversion scope: quantities by DTE IM number across the program, quantities by CWO and IM, and a short list of materials pending DTE IM confirmation. Quantities are reconciled across three independent sources: DTE CUE estimate material summaries, construction bills of material, and confirmed supplier order records.
B18: COVERAGE
B19: This package covers the 15 reconciled overhead CWOs listed on the Summary by CWO tab — approximately 97% of program install quantities when compared against DTE’s Maximo work-order quantities. Reconciliation of the remaining small CWOs (four recloser CWOs and CWO 73303193) will follow under separate cover. Underground CWOs removed from the program by credit are excluded.
B23: CONTENTS
B24: Summary by CWO | C24: Program headline quantities (poles, conductor, transformers) and material line counts per CWO.
B25: Quantities by DTE IM | C25: One row per confirmed DTE IM across the program: BOM, CUE-required, variance, and confirmed ordered quantities.
B26: Quantities by CWO and IM | C26: Full detail — each DTE IM within each contributing CWO.
B27: Pending IM Confirmation | C27: Materials without a confirmed DTE IM number; DTE confirmation requested.
B28: Basis and Exclusions | C28: Sources, methodology, exclusions, and reservation of rights.
B30: RESERVATION OF RIGHTS
B31: This transmittal is provided for quantity reconciliation and coordination purposes only. It documents material quantities derived from DTE CUE estimates, construction bills of material, and confirmed supplier order records. Nothing herein constitutes agreement to any credit, back-charge, price adjustment, or change to contract scope or value under Contract 4400008681, and all rights under the contract are expressly reserved. Any adjustment arising from these quantities shall be processed exclusively through the contract change process.

Sheet Summary by CWO
B2: Program Headline Quantities by CWO
B3: Source: reconciled DTE CUE estimates and construction BOMs (Jul 2026 reconciliation).
B5: CWO | C5: Pole Replacements | D5: Bare Conductor (ft) | E5: Transformers | F5: Material Line Items
B6: 73232522 | C6: 30 | D6: 9776 | E6: 12 | F6: =COUNTIF('Quantities by CWO and IM'!$B$6:$B$1593,B6) -> 109
B7: 73234686 | C7: 23 | D7: 8311 | E7: 9 | F7: =COUNTIF('Quantities by CWO and IM'!$B$6:$B$1593,B7) -> 154
B8: 73239897 | C8: 25 | D8: 5946 | E8: 7 | F8: =COUNTIF('Quantities by CWO and IM'!$B$6:$B$1593,B8) -> 93
B9: 73239916 | C9: 33 | D9: 6580 | E9: 13 | F9: =COUNTIF('Quantities by CWO and IM'!$B$6:$B$1593,B9) -> 108
B10: 73239926 | C10: 25 | D10: 6114 | E10: 5 | F10: =COUNTIF('Quantities by CWO and IM'!$B$6:$B$1593,B10) -> 132
B11: 73240913 | C11: 36 | D11: 22026 | E11: 9 | F11: =COUNTIF('Quantities by CWO and IM'!$B$6:$B$1593,B11) -> 156
B12: 73242557 | C12: 20 | D12: 4757 | E12: 4 | F12: =COUNTIF('Quantities by CWO and IM'!$B$6:$B$1593,B12) -> 134
B13: 73242619 | C13: 18 | D13: 8446 | E13: 6 | F13: =COUNTIF('Quantities by CWO and IM'!$B$6:$B$1593,B13) -> 96
B14: 73244139 | C14: 38 | D14: 8978 | E14: 6 | F14: =COUNTIF('Quantities by CWO and IM'!$B$6:$B$1593,B14) -> 124
B15: 73279347 | C15: 0 | D15: 145 | E15: 0 | F15: =COUNTIF('Quantities by CWO and IM'!$B$6:$B$1593,B15) -> 68
B16: 73301547 | C16: 32 | D16: 13450 | E16: 6 | F16: =COUNTIF('Quantities by CWO and IM'!$B$6:$B$1593,B16) -> 106
B17: 73301585 | C17: 33 | D17: 16885 | E17: 3 | F17: =COUNTIF('Quantities by CWO and IM'!$B$6:$B$1593,B17) -> 104
... B20: 73802595 | C20: 1 | D20: 17247 | E20: 4 | F20: =COUNTIF('Quantities by CWO and IM'!$B$6:$B$1593,B20) -> 95
B21: TOTAL | C21: =SUM(C6:C20) -> 332 | D21: =SUM(D6:D20) -> 140289 | E21: =SUM(E6:E20) -> 84 | F21: =SUM(F6:F20) -> 1588
B23: Pole, conductor, and transformer counts are program headline quantities from the CWO-level reconciliation; conductor is bare primary/neutral wire and excludes triplex/secondary cable. Material line items counts the CWO-and-IM detail rows in this package.

Sheet Quantities by DTE IM
B2: Overhead Material Quantities by DTE IM — Program-Wide
B3: One row per confirmed DTE IM across all 15 reconciled CWOs. Ordered Qty reflects confirmed supplier order records as of 7/28/2026 and excludes DTE-furnished job stock.
B5: DTE IM | C5: Material Description | D5: UOM | E5: CWO Count | F5: BOM Qty | G5: CUE Required Qty | H5: Variance (CUE − BOM) | I5: Ordered Qty (as of 7/28/26) | J5: CWO Numbers
B6: 100003861 | C6: CLIP_STATIC,INSULTR DISTRBTN,5/8 IN DIA | D6: EA | E6: 15 | F6: 186 | G6: 196 | H6: =N(G6)-N(F6) -> 10 | I6: 200 | J6: 73232522; 73234686; 73239897; 73239916; 73239926; 73240913; 73242557; 73242619; 73244139; 73279347; 73301547; 73301585; 73305080; 73358165; 73802595
B7: 100018327 | C7: WASHER_FLAT,5/8 IN ID,1-3/4 IN OD,WROUGH | D7: EA | E7: 15 | F7: 3086 | G7: 2280 | H7: =N(G7)-N(F7) -> -806 | I7: 3086 | J7: 73232522; 73234686; 73239897; 73239916; 73239926; 73240913; 73242557; 73242619; 73244139; 73279347; 73301547; 73301585; 73305080; 73358165; 73802595
B8: 100019342 | C8: STRAP_GROUND,GALV STL | D8: EA | E8: 15 | F8: 494 | G8: 764 | H8: =N(G8)-N(F8) -> 270 | I8: 500 | J8: 73232522; 73234686; 73239897; 73239916; 73239926; 73240913; 73242557; 73242619; 73244139; 73279347; 73301547; 73301585; 73305080; 73358165; 73802595
B9: 100020717 | C9: ROD_GROUND,5/8 IN DIA,CRBN STL,8 FT LG | D9: EA | E9: 15 | F9: 350 | G9: 382 | H9: =N(G9)-N(F9) -> 32 | I9: 350 | J9: 73232522; 73234686; 73239897; 73239916; 73239926; 73240913; 73242557; 73242619; 73244139; 73279347; 73301547; 73301585; 73305080; 73358165; 73802595
B10: 100021354 | C10: BOLT_MACHINE,5/8 IN DIA,11 TPI,16 IN LG, | D10: EA | E10: 15 | F10: 1543 | G10: 1112 | H10: =N(G10)-N(F10) -> -431 | I10: 1729 | J10: 73232522; 73234686; 73239897; 73239916; 73239926; 73240913; 73242557; 73242619; 73244139; 73279347; 73301547; 73301585; 73305080; 73358165; 73802595
B11: 100023899 | C11: BOLT_MACHINE,5/8 IN DIA,11 TPI,12 IN LG, | D11: EA | E11: 15 | F11: 2231 | G11: 2391 | H11: =N(G11)-N(F11) -> 160 | I11: 2259 | J11: 73232522; 73234686; 73239897; 73239916; 73239926; 73240913; 73242557; 73242619; 73244139; 73279347; 73301547; 73301585; 73305080; 73358165; 73802595
B12: 100026047 | C12: WASHER_CURVED,3 IN X 3 IN,MALLEABLE/DUCT | D12: EA | E12: 15 | F12: 3534 | G12: 3696 | H12: =N(G12)-N(F12) -> 162 | I12: 3534 | J12: 73232522; 73234686; 73239897; 73239916; 73239926; 73240913; 73242557; 73242619; 73244139; 73279347; 73301547; 73301585; 73305080; 73358165; 73802595
B13: 100027139 | C13: STUD_INSULATOR,3/4 IN DIA X 7 IN LG,GALV | D13: EA | E13: 15 | F13: 339 | G13: 327 | H13: =N(G13)-N(F13) -> -12 | I13: 339 | J13: 73232522; 73234686; 73239897; 73239916; 73239926; 73240913; 73242557; 73242619; 73244139; 73279347; 73301547; 73301585; 73305080; 73358165; 73802595
B14: 100034502 | C14: BOLT_EYE,5/8 IN DIA,11 TPI,12 IN LG,GALV | D14: EA | E14: 15 | F14: 560 | G14: 342 | H14: =N(G14)-N(F14) -> -218 | I14: 560 | J14: 73232522; 73234686; 73239897; 73239916; 73239926; 73240913; 73242557; 73242619; 73244139; 73279347; 73301547; 73301585; 73305080; 73358165; 73802595
B15: 100036719 | C15: NUT_EYE,5/8 IN,GALV STL | D15: EA | E15: 15 | F15: 517 | G15: 516 | H15: =N(G15)-N(F15) -> -1 | I15: 517 | J15: 73232522; 73234686; 73239897; 73239916; 73239926; 73240913; 73242557; 73242619; 73244139; 73279347; 73301547; 73301585; 73305080; 73358165; 73802595
B16: 100043531 | C16: INSULATOR_ELECT,CLAMP TOP,28KV,POLYMER,I | D16: EA | E16: 15 | F16: 1454 | G16: 1078 | H16: =N(G16)-N(F16) -> -376 | I16: 1448 | J16: 73232522; 73234686; 73239897; 73239916; 73239926; 73240913; 73242557; 73242619; 73244139; 73279347; 73301547; 73301585; 73305080; 73358165; 73802595
B17: 100045998 | C17: ARRESTER_SURGE,DISTRBTN,POLYMER,METL OXI | D17: EA | E17: 15 | F17: 305 | G17: 227 | H17: =N(G17)-N(F17) -> -78 | I17: 305 | J17: 73232522; 73234686; 73239897; 73239916; 73239926; 73240913; 73242557; 73242619; 73244139; 73279347; 73301547; 73301585; 73305080; 73358165; 73802595
... B30: 100076666 | C30: BRACKET_MNTNG,NEMA,ARSTR,3/8 IN X 1-3/4 | D30: EA | E30: 14 | F30: 402 | G30: 505 | H30: =N(G30)-N(F30) -> 103 | I30: 402 | J30: 73232522; 73234686; 73239897; 73239916; 73239926; 73240913; 73242557; 73242619; 73244139; 73279347; 73301547; 73301585; 73305080; 73802595
B31: 100100489 | C31: CABLE_INSUL,XLPE,6 AWG,CU,SOLID,1 CONDUC | E31: 14 | F31: 3325 | G31: 5692 | H31: =N(G31)-N(F31) -> 2367 | J31: 73232522; 73234686; 73239897; 73239916; 73239926; 73240913; 73242557; 73242619; 73244139; 73279347; 73301547; 73301585; 73305080; 73802595
B32: 100317966 | C32: CONNECTOR_OVERHEAD,HOT LINE,NO. 6-4/0,0. | D32: EA | E32: 14 | F32: 251 | G32: 249 | H32: =N(G32)-N(F32) -> -2 | I32: 251 | J32: 73232522; 73234686; 73239897; 73239916; 73239926; 73240913; 73242557; 73242619; 73244139; 73279347; 73301547; 73301585; 73305080; 73802595
B33: 100319272 | C33: CONNECTOR_CABLE,GRNDING,CU,NO. 6-2/0 | D33: EA | E33: 14 | F33: 147 | G33: 374 | H33: =N(G33)-N(F33) -> 227 | I33: 169 | J33: 73232522; 73234686; 73239897; 73239916; 73239926; 73240913; 73242557; 73242619; 73244139; 73279347; 73301547; 73301585; 73305080; 73802595
B34: 100012641 | C34: BOLT_EYE,5/8 IN DIA,11 TPI,8 IN LG,GALV | D34: EA | E34: 13 | F34: 136 | G34: 154 | H34: =N(G34)-N(F34) -> 18 | I34: 136 | J34: 73232522; 73234686; 73239897; 73239916; 73239926; 73240913; 73242557; 73242619; 73244139; 73279347; 73301585; 73358165; 73802595
B35: 100039650 | C35: CLAMP_DEADEND,STRGHT LINE,ALUM ALLOY,ACS | D35: EA | E35: 13 | F35: 672 | G35: 572 | H35: =N(G35)-N(F35) -> -100 | I35: 866 | J35: 73232522; 73234686; 73239897; 73239916; 73239926; 73240913; 73242557; 73242619; 73244139; 73279347; 73301547; 73301585; 73802595
B36: 100039761 | C36: CABLE_BARE,1/0 AWG,6 X 1 STRANDD,6095 FT | D36: FT | E36: 13 | F36: 64366 | G36: 57894 | H36: =N(G36)-N(F36) -> -6472 | I36: 60950 | J36: 73232522; 73234686; 73239897; 73239916; 73239926; 73240913; 73242557; 73242619; 73244139; 73301547; 73301585; 73358165; 73802595
B37: 100057672 | C37: ROD_ANCHOR,EXT,1-1/2 IN DIA,GALV STL,3-1 | D37: EA | E37: 13 | F37: 89 | G37: 83 | H37: =N(G37)-N(F37) -> -6 | I37: 173 | J37: 73232522; 73234686; 73239897; 73239916; 73239926; 73240913; 73242557; 73242619; 73244139; 73279347; 73301585; 73305080; 73802595
B38: 100081480 | C38: CONNECTOR_CABLE,TAP,BRNZ,NO. 6,SPLIT BOL | D38: EA | E38: 13 | F38: 26 | G38: 124 | H38: =N(G38)-N(F38) -> 98 | I38: 26 | J38: 73232522; 73234686; 73239897; 73239916; 73239926; 73240913; 73242557; 73242619; 73244139; 73279347; 73301547; 73301585; 73802595
B39: 100095397 | C39: CROSSARM_ASSY,DEADEND WITH CENTR BRKT,10 | D39: EA | E39: 13 | F39: 50 | G39: 51 | H39: =N(G39)-N(F39) -> 1 | I39: 50 | J39: 73234686; 73239897; 73239916; 73239926; 73240913; 73242557; 73244139; 73279347; 73301547; 73301585; 73305080; 73358165; 73802595
B40: 100095608 | C40: CROSSARM_ASSY,DEADEND WITH CENTR BRKT,8 | D40: EA | E40: 13 | F40: 103 | G40: 85 | H40: =N(G40)-N(F40) -> -18 | I40: 103 | J40: 73232522; 73234686; 73239897; 73239916; 73239926; 73240913; 73242557; 73242619; 73244139; 73279347; 73301547; 73301585; 73802595
B41: 100097691 | C41: CLAMP_JUMPER,BRNZ,CU,8-1/0 | D41: EA | E41: 13 | F41: 514 | G41: 747 | H41: =N(G41)-N(F41) -> 233 | I41: 514 | J41: 73232522; 73234686; 73239897; 73239916; 73239926; 73240913; 73242557; 73242619; 73244139; 73279347; 73301547; 73301585; 73802595
B42: 100105615 | C42: BOLT_MACHINE,1/2 IN DIA,13 TPI,1-1/2 IN | D42: EA | E42: 13 | F42: 259 | G42: 307 | H42: =N(G42)-N(F42) -> 48 | I42: 259 | J42: 73232522; 73234686; 73239897; 73239916; 73239926; 73240913; 73242557; 73242619; 73244139; 73279347; 73301547; 73301585; 73802595
B43: 100110224 | C43: WASHER_SQUARE,9/16 IN ID,2 IN X 2 IN,1/8 | D43: EA | E43: 13 | F43: 167 | G43: 570 | H43: =N(G43)-N(F43) -> 403 | I43: 50 | J43: 73232522; 73234686; 73239916; 73239926; 73240913; 73242557; 73242619; 73244139; 73279347; 73301547; 73301585; 73305080; 73802595
... B79: 100097576 | C79: INSULATOR_STRAIN,DEADEND,3 IN SPOOL,PORC | D79: EA | E79: 10 | F79: 150 | G79: 188 | H79: =N(G79)-N(F79) -> 38 | I79: 195 | J79: 73232522; 73234686; 73239897; 73239916; 73239926; 73240913; 73242557; 73242619; 73244139; 73301547
B80: 100109390 | C80: LEAD_ELECT,SECNDRY,10 FT LG,CU,2 AWG SOL | E80: 10 | F80: 0 | G80: 147 | H80: =N(G80)-N(F80) -> 147 | J80: 73232522; 73234686; 73239897; 73239916; 73239926; 73240913; 73242619; 73244139; 73301547; 73802595
B81: 100115939 | C81: CABLE_BARE,636KCMIL,ALUM,37 STRAND,6200 | D81: FT | E81: 10 | F81: 86462 | G81: 61866 | H81: =N(G81)-N(F81) -> -24596 | I81: 86800 | J81: 73234686; 73239926; 73240913; 73242557; 73244139; 73301547; 73301585; 73305080; 73358165; 73802595
B82: 100319274 | C82: RACK_INSULATOR,HD TRIPLX SECNDRY,PORCLN | D82: EA | E82: 10 | F82: 354 | G82: 324 | H82: =N(G82)-N(F82) -> -30 | I82: 354 | J82: 73232522; 73234686; 73239897; 73239916; 73239926; 73240913; 73242557; 73242619; 73244139; 73301547
B83: 100319350 | C83: RACK_INSULATOR,HD SECNDRY,PORCLN SPOOLS, | D83: EA | E83: 10 | F83: 177 | G83: 12 | H83: =N(G83)-N(F83) -> -165 | I83: 180 | J83: 73232522; 73234686; 73239897; 73239916; 73239926; 73240913; 73242557; 73242619; 73244139; 73358165
B84: 100339982 | C84: FUSE_ASSY,CURLMTG,7.6KV,20 AMP | D84: EA | E84: 10 | F84: 69 | G84: 100 | H84: =N(G84)-N(F84) -> 31 | I84: 44 | J84: 73232522; 73234686; 73239897; 73239916; 73239926; 73240913; 73242619; 73244139; 73301547; 73802595
B85: 100339983 | C85: FUSE_ASSY,CURLMTG,7.6KV,30 AMP | D85: EA | E85: 10 | F85: 69 | G85: 78 | H85: =N(G85)-N(F85) -> 9 | I85: 94 | J85: 73234686; 73239897; 73239916; 73239926; 73240913; 73242557; 73242619; 73244139; 73301547; 73301585
B86: 100008748 | C86: INSULATOR_STRAIN,GUY,27 IN LG,FBRGLAS 18 | D86: EA | E86: 9 | F86: 88 | G86: 40 | H86: =N(G86)-N(F86) -> -48 | I86: 100 | J86: 73232522; 73234686; 73239897; 73239916; 73239926; 73242557; 73242619; 73244139; 73305080
B87: 100009193 | C87: GUY_ASSY,5/16 IN DIA,125 FT LG,EHS STL S | E87: 9 | F87: 50 | G87: 62 | H87: =N(G87)-N(F87) -> 12 | J87: 73232522; 73234686; 73239916; 73239926; 73240913; 73242557; 73242619; 73244139; 73301585
B88: 100015054 | C88: Connector Wedge Al/Cu #6-#2 | D88: EA | E88: 9 | F88: 0 | G88: 0 | H88: =N(G88)-N(F88) -> 0 | I88: 360 | J88: 73232522; 73239897; 73239926; 73242557; 73242619; 73244139; 73305080; 73358165; 73802595
B89: 100328220 | C89: BRACKET_MNTNG,STNDOFF,INSULTR,24 IN LG,F | D89: EA | E89: 9 | F89: 246 | G89: 91 | H89: =N(G89)-N(F89) -> -155 | I89: 260 | J89: 73232522; 73234686; 73239897; 73239916; 73239926; 73240913; 73242557; 73242619; 73244139
...

Sheet Quantities by CWO and IM
B2: Overhead Material Quantities by CWO and DTE IM
B3: Each row is one DTE IM within one contributing CWO. Same sources and exclusions as the program-wide tab.
B5: CWO | C5: DTE IM | D5: Material Description | E5: UOM | F5: BOM Qty | G5: CUE Required Qty | H5: Variance (CUE − BOM) | I5: Ordered Qty (as of 7/28/26)
B6: 73232522 | C6: 100001517 | D6: LINK_FUSE,UNV,10 AMP | F6: 0 | G6: 1 | H6: =N(G6)-N(F6) -> 1
B7: 73232522 | C7: 100003861 | D7: CLIP_STATIC,INSULTR DISTRBTN,5/8 IN DIA | F7: 0 | G7: 5 | H7: =N(G7)-N(F7) -> 5
B8: 73232522 | C8: 100004757 | D8: MARKER_GUY,PLSTC,1 IN TO 2-1/2 IN DIA,PE | E8: EA | F8: 8 | G8: 1 | H8: =N(G8)-N(F8) -> -7 | I8: 8
B9: 73232522 | C9: 100008297 | D9: INSULATOR_PIN,1 IN DIA,PORCLN,F-NECK,LAR | E9: EA | F9: 15 | G9: 18 | H9: =N(G9)-N(F9) -> 3 | I9: 15
B10: 73232522 | C10: 100008748 | D10: INSULATOR_STRAIN,GUY,27 IN LG,FBRGLAS 18 | E10: EA | F10: 16 | G10: 1 | H10: =N(G10)-N(F10) -> -15 | I10: 100
B11: 73232522 | C11: 100009193 | D11: GUY_ASSY,5/16 IN DIA,125 FT LG,EHS STL S | F11: 0 | G11: 2 | H11: =N(G11)-N(F11) -> 2
B12: 73232522 | C12: 100012641 | D12: BOLT_EYE,5/8 IN DIA,11 TPI,8 IN LG,GALV | F12: 0 | G12: 12 | H12: =N(G12)-N(F12) -> 12
B13: 73232522 | C13: 100015054 | D13: Connector Wedge Al/Cu #6-#2 | E13: EA | F13: 0 | G13: 0 | H13: =N(G13)-N(F13) -> 0 | I13: 60
B14: 73232522 | C14: 100017083 | D14: 5/8" ground rod connector | E14: EA | F14: 10 | G14: 0 | H14: =N(G14)-N(F14) -> -10 | I14: 10
B15: 73232522 | C15: 100017594 | D15: INSULATOR_SUSP,DEADEND,4-1/4 IN,PORCLN,S | E15: EA | F15: 21 | G15: 12 | H15: =N(G15)-N(F15) -> -9 | I15: 192
B16: 73232522 | C16: 100017876 | D16: CONNECTOR_CABLE,TAP,BRNZ,CU,NO. 2 | F16: 0 | G16: 2 | H16: =N(G16)-N(F16) -> 2
B17: 73232522 | C17: 100018327 | D17: WASHER_FLAT,5/8 IN ID,1-3/4 IN OD,WROUGH | E17: EA | F17: 146 | G17: 106 | H17: =N(G17)-N(F17) -> -40 | I17: 146
B18: 73232522 | C18: 100019342 | D18: STRAP_GROUND,GALV STL | F18: 0 | G18: 60 | H18: =N(G18)-N(F18) -> 60
B19: 73232522 | C19: 100020717 | D19: ROD_GROUND,5/8 IN DIA,CRBN STL,8 FT LG | E19: EA | F19: 10 | G19: 30 | H19: =N(G19)-N(F19) -> 20 | I19: 10
B20: 73232522 | C20: 100020751 | D20: WIRE_TIE,NO. 4,ALUM,132 IN LG | F20: 0 | G20: 27 | H20: =N(G20)-N(F20) -> 27
B21: 73232522 | C21: 100021353 | D21: LINK_FUSE,UNV,30 AMP | E21: EA | F21: 10 | G21: 0 | H21: =N(G21)-N(F21) -> -10 | I21: 10
B22: 73232522 | C22: 100021354 | D22: BOLT_MACHINE,5/8 IN DIA,11 TPI,16 IN LG, | E22: EA | F22: 93 | G22: 80 | H22: =N(G22)-N(F22) -> -13 | I22: 125
B23: 73232522 | C23: 100022671 | D23: LINK_FUSE,UNV,20 AMP | F23: 0 | G23: 5 | H23: =N(G23)-N(F23) -> 5
B24: 73232522 | C24: 100023899 | D24: BOLT_MACHINE,5/8 IN DIA,11 TPI,12 IN LG, | E24: EA | F24: 0 | G24: 210 | H24: =N(G24)-N(F24) -> 210 | I24: 12
B25: 73232522 | C25: 100026047 | D25: WASHER_CURVED,3 IN X 3 IN,MALLEABLE/DUCT | E25: EA | F25: 300 | G25: 319 | H25: =N(G25)-N(F25) -> 19 | I25: 300
B26: 73232522 | C26: 100027139 | D26: STUD_INSULATOR,3/4 IN DIA X 7 IN LG,GALV | F26: 0 | G26: 2 | H26: =N(G26)-N(F26) -> 2
B27: 73232522 | C27: 100030339 | D27: CABLE_INSUL,XLPE,1/0 AWG,ALUM,7 STRANDD | F27: 0 | G27: 1 | H27: =N(G27)-N(F27) -> 1
B28: 73232522 | C28: 100032667 | D28: BOLT_MACHINE,5/8 IN DIA,11 TPI,10 IN LG, | F28: 0 | G28: 3 | H28: =N(G28)-N(F28) -> 3
B29: 73232522 | C29: 100032688 | D29: ROPE_WIRE,5/16 IN DIA,STL,5000 FT LG REE | F29: 0 | G29: 250 | H29: =N(G29)-N(F29) -> 250
B30: 73232522 | C30: 100033980 | D30: SCREW_LAG,1/2 IN DIA,4 IN LG,HOT DIP GAL | F30: 0 | G30: 4 | H30: =N(G30)-N(F30) -> 4
B31: 73232522 | C31: 100034502 | D31: BOLT_EYE,5/8 IN DIA,11 TPI,12 IN LG,GALV | E31: EA | F31: 60 | G31: 12 | H31: =N(G31)-N(F31) -> -48 | I31: 60
B32: 73232522 | C32: 100035876 | D32: ANCHOR_SCREW,TD, HELIX SHAFT ASSY,8-10 I | E32: EA | F32: 4 | G32: 7 | H32: =N(G32)-N(F32) -> 3 | I32: 4
B33: 73232522 | C33: 100036719 | D33: NUT_EYE,5/8 IN,GALV STL | E33: EA | F33: 22 | G33: 15 | H33: =N(G33)-N(F33) -> -7 | I33: 22
B34: 73232522 | C34: 100036858 | D34: BRACKET_SUPPORT,TERMINATN/ARSTR | E34: EA | F34: 6 | G34: 0 | H34: =N(G34)-N(F34) -> -6 | I34: 24
B35: 73232522 | C35: 100038906 | D35: GUY_ASSY,5/16 IN DIA,165 FT LG,EHS STL S | F35: 0 | G35: 1 | H35: =N(G35)-N(F35) -> 1
B36: 73232522 | C36: 100039650 | D36: CLAMP_DEADEND,STRGHT LINE,ALUM ALLOY,ACS | E36: EA | F36: 61 | G36: 43 | H36: =N(G36)-N(F36) -> -18 | I36: 61
B37: 73232522 | C37: 100039652 | D37: ROD_ANCHOR,5/8 IN DIA,GALV STL,7 FT LG,T | F37: 0 | G37: 3 | H37: =N(G37)-N(F37) -> 3
B38: 73232522 | C38: 100039653 | D38: ADAPTER_PIPE,GUY,18 IN LG,GALV STL | F38: 0 | G38: 7 | H38: =N(G38)-N(F38) -> 7
B39: 73232522 | C39: 100039661 | D39: BOLT_MACHINE,5/8 IN DIA,11 TPI,2 IN LG,G | F39: 0 | G39: 4 | H39: =N(G39)-N(F39) -> 4
B40: 73232522 | C40: 100039663 | D40: WASHER_LOCKING,DBL COIL,5/8 IN,GALV STL | F40: 0 | G40: 68 | H40: =N(G40)-N(F40) -> 68
B41: 73232522 | C41: 100039761 | D41: CABLE_BARE,1/0 AWG,6 X 1 STRANDD,6095 FT | E41: FT | F41: 8300 | G41: 8801 | H41: =N(G41)-N(F41) -> 501 | I41: 8667.4605
B42: 73232522 | C42: 100042455 | D42: DEADEND_PREFORMED,GRIP,24 IN LG,STL,ACSR | F42: 0 | G42: 7 | H42: =N(G42)-N(F42) -> 7
...

Sheet Pending IM Confirmation
B2: Materials Pending DTE IM Confirmation
B3: These materials appear in construction BOMs or supplier order records without a confirmed DTE IM number. The closest candidate IM from DTE’s item master is proposed where one exists. DTE is requested to confirm or correct the IM assignment in the yellow column; quantities shown are excluded from the confirmed-IM tabs until then.
B5: Material Description | C5: BOM Qty | D5: UOM | E5: Ordered Qty (unresolved) | F5: Proposed DTE IM (candidate) | G5: Match Confidence | H5: CWO Numbers | I5: DTE Confirmed IM / Response
B6: Ground Wire Molding | C6: 309 | D6: EA | F6: 100075415 | G6: MEDIUM DESCRIPTION; similarity 53% | H6: 73232522; 73234686; 73239897; 73239916; 73239926; 73240913; 73242557; 73242619; 73244139; 73301547; 73301585; 73305080; 73358165
B7: Ground Wire Staples | C7: 3050 | F7: 100101751 | G7: VERY LOW DESCRIPTION; similarity 0% | H7: 73232522; 73234686; 73239897; 73239916; 73239926; 73240913; 73242557; 73242619; 73244139; 73301547; 73301585; 73305080; 73358165
B8: Molding Staples | C8: 2915 | F8: 100101751 | G8: VERY LOW DESCRIPTION; similarity 0% | H8: 73232522; 73234686; 73239897; 73239916; 73239926; 73240913; 73242557; 73242619; 73244139; 73301547; 73301585; 73305080; 73358165
B9: 45' CLASS 3 PINE | C9: 83 | D9: EA | F9: 100088575 | G9: LOW DESCRIPTION; similarity 43% | H9: 73232522; 73234686; 73239897; 73239916; 73239926; 73240913; 73242557; 73242619; 73244139; 73301547; 73358165
B10: 7/16" Guy Wire, Rope Wire | C10: 5000 | D10: FT | F10: 100329907 | G10: MEDIUM DESCRIPTION; similarity 68% | H10: 73232522; 73239926; 73240913; 73242557; 73242619; 73301547; 73301585; 73305080; 73802595
B11: #6 AWG Stranded Bare Copper Wire | C11: 10305 | F11: 100039761 | G11: LOW; similarity 42% | H11: 73232522; 73239897; 73239926; 73242557; 73242619; 73244139; 73305080; 73358165
B12: Crimipit, #6 AWG to #6 AWG | C12: 345 | F12: 100100489 | G12: LOW; similarity 40% | H12: 73232522; 73239897; 73239926; 73242557; 73242619; 73244139; 73305080; 73358165
B13: Wire #2 Cu Sol Bare SD 2500ft reels | D13: FT | E13: 5192.8333 | F13: 100048429 | G13: LOW; similarity 32% | H13: 73234686; 73239916; 73240913; 73279347; 73301547; 73301585; 73802595
B14: 45' CLASS 3 CEDAR | C14: 84 | D14: EA | E14: 84 | F14: 100289875 | G14: HIGH; similarity 85% | H14: 73232522; 73239897; 73239916; 73239926; 73240913; 73242557; 73242619
B15: 5/16" Guy Wire, Rope Wire | C15: 5575 | F15: 100032688 | G15: MEDIUM DESCRIPTION; similarity 66% | H15: 73232522; 73239926; 73240913; 73242557; 73242619; 73244139
B16: Crimipit, 2 AWG to 2 AWG | C16: 310 | F16: 100004757 | G16: LOW; similarity 40% | H16: 73234686; 73239916; 73240913; 73301547; 73301585
B17: 55' CLASS 1 PINE | C17: 26 | D17: EA | F17: 100042242 | G17: LOW DESCRIPTION; similarity 43% | H17: 73234686; 73239926; 73240913; 73244139; 73305080
B18: 60' CLASS 1 PINE | C18: 7 | D18: EA | F18: 100042243 | G18: LOW DESCRIPTION; similarity 43% | H18: 73234686; 73240913; 73244139; 73305080; 73802595
B19: 2 AWG Stranded Bare Copper Wire | C19: 8150 | F19: 100048429 | G19: LOW DESCRIPTION; similarity 42% | H19: 73234686; 73239916; 73240913; 73301585
B20: 5/8" Lock Nut | C20: 90 | F20: 100036719 | G20: MEDIUM; similarity 64% | H20: 73232522; 73239897; 73242619; 73305080
B21: 5/8" x 16" Machine Bolt, Galvanized Steel | C21: 212 | F21: 100024354 | G21: HIGH; similarity 80% | H21: 73232522; 73239897; 73242557; 73242619
B22: 50' CLASS 1 PINE | C22: 14 | D22: EA | E22: 3 | F22: 100069509 | G22: LOW DESCRIPTION; similarity 43% | H22: 73234686; 73239926; 73242557; 73301585
B23: 50' CLASS 3 PINE | C23: 43 | D23: EA | F23: 100025788 | G23: VERY LOW DESCRIPTION; similarity 21% | H23: 73234686; 73240913; 73242557; 73301585
B24: Washer Square 2x2 1/2 | D24: EA | E24: 147 | F24: 100052587 | G24: MEDIUM; similarity 67% | H24: 73240913; 73242557; 73301547; 73301585
B25: 7/16" Guy Grip | C25: 36 | D25: EA | E25: 26 | F25: 100074493 | G25: LOW; similarity 41% | H25: 73232522; 73239897; 73305080
B26: Armor Rod Alum. Alloy | C26: 65 | D26: EA | F26: 100074602 | G26: HIGH DESCRIPTION; similarity 81% | H26: 73234686; 73242557; 73301585
B27: Straight Line Deadend Clamp | C27: 231 | F27: 100039650 | G27: HIGH DESCRIPTION; similarity 87% | H27: 73234686; 73301547; 73301585
B28: 45' Class 1 CEDAR | C28: 5 | D28: EA | E28: 5 | F28: 100289876 | G28: HIGH; similarity 85% | H28: 73232522; 73239916; 73239926
B29: 55' CLASS 3 PINE | C29: 14 | D29: EA | F29: 100107159 | G29: LOW DESCRIPTION; similarity 43% | H29: 73234686; 73240913; 73305080
B30: Armor Rod Alum. Alloy | C30: 29 | F30: 100074602 | G30: HIGH DESCRIPTION; similarity 81% | H30: 73240913; 73305080
B31: Machine Bolt, Galv. Steel | C31: 28 | F31: 100099738 | G31: HIGH; similarity 85% | H31: 73232522; 73802595
B32: 5/16" Guy Grip | C32: 24 | D32: EA | E32: 6 | F32: 100009193 | G32: MEDIUM; similarity 59% | H32: 73232522; 73239897
B33: Single Phase Fiberglass Mounting Bracket | C33: 31 | F33: 100310426 | G33: VERY LOW DESCRIPTION; similarity 16% | H33: 73232522; 73242557
B34: Bracket Mounting, Shield Wire, Malleable/Duct | C34: 7 | F34: 100088112 | G34: MEDIUM DESCRIPTION; similarity 62% | H34: 73234686; 73242557
B35: 40' CLASS 3 CEDAR | C35: 3 | D35: EA | E35: 3 | F35: 100313938 | G35: HIGH; similarity 85% | H35: 73240913; 73242557
B36: 40' CLASS 3 PINE | C36: 4 | D36: EA | F36: 100018203 | G36: LOW DESCRIPTION; similarity 43% | H36: 73239926; 73244139
B37: 45' CLASS 1 PINE | C37: 5 | D37: EA | F37: 100061029 | G37: LOW DESCRIPTION; similarity 43% | H37: 73234686; 73242619
B38: 50' CLASS 2 PINE | C38: 2 | D38: EA | F38: 100024362 | G38: LOW DESCRIPTION; similarity 43% | H38: 73234686; 73240913
B39: 1/0 AWG Bare | C39: 2600 | F39: 100039761 | G39: HIGH DESCRIPTION; similarity 82% | H39: 73301547
B40: 2 Awg BARE | C40: 375 | D40: FT | F40: 100048429 | G40: HIGH DESCRIPTION; similarity 79% | H40: 73242557
B41: 2 AWG Bare Copper | C41: 780 | D41: FT | F41: 100048429 | G41: MEDIUM DESCRIPTION; similarity 61% | H41: 73305080
B42: 2AWG Stranded Bare Copper Wire | C42: 2600 | F42: 100048429 | G42: VERY LOW DESCRIPTION; similarity 16% | H42: 73301547
...

Sheet Basis and Exclusions
B2: Basis of Quantities, Exclusions, and Reservation of Rights
B4: SOURCES
B5: DTE CUE estimate material summaries | C5: Per-CWO material requirement quantities by DTE IM (“CUE Required Qty”).
B6: Construction bills of material | C6: Per-CWO construction BOM quantities (“BOM Qty”).
B7: Supplier order records (PLS) | C7: Confirmed order allocations by CWO and IM; dollars cross-checked to the PLS purchase order report as of 7/28/2026.
B8: DTE Maximo work-order quantities | C8: Used as a cross-check only; program install quantities agree within ~5% overall and within 0.5% on conductor.
B10: METHODOLOGY
B11: • Quantities were reconciled independently for each of the 15 CWOs, then rolled up by DTE IM at the program level.
B12: • Full 18-digit CUE item numbers were extracted from the CUE document text and normalized to 9-digit DTE IM numbers.
B13: • Order-only line items carrying a valid or suffix-normalized DTE IM are included; unresolved items appear on the Pending IM Confirmation tab.
B14: • Variance columns are calculated in-sheet (CUE Required − BOM) and recompute automatically.
B16: EXCLUSIONS AND PENDING ITEMS
B17: • DTE-furnished job stock is not included in ordered quantities; CUE Required quantities include all material regardless of furnishing party.
B18: • Per-IM delivered quantities are pending a line-item export from the supplier (IM, qty ordered, qty delivered, PO number, promise date) and are not represented here.
B19: • Underground CWOs removed from the program by credit are excluded in their entirety.
B20: • Four recloser CWOs and CWO 73303193 are outside this reconciliation set and will follow under separate cover.
B21: • Where a DTE IM spans mixed units of measure across sources, totals should be read with the UOM column; mixed-UOM lines are flagged in our working files.
B23: RESERVATION OF RIGHTS
B24: This package is a quantity reconciliation provided for informational and coordination purposes at DTE’s request. It is not an agreement to any credit, back-charge, price adjustment, or change to the scope or value of Contract 4400008681. All rights and remedies under the contract are expressly reserved. Any commercial adjustment arising from or related to the quantities herein shall be initiated and processed exclusively through the contract change process.
